Workbook

Sheet README_Istruzioni
B2: STRUMENTO DI VALUTAZIONE DEL RISCHIO STRESS LAVORO-CORRELATO (SLC)
B3: Basato su: Linee Guida INAIL 2017 | Monografia INAIL Aprile 2025 | D.Lgs. 81/08
B5: RIFERIMENTI NORMATIVI
B6: D.Lgs. 81/2008 | C6: Art. 28 c.1: obbligo di valutazione di tutti i rischi, compresi quelli da stress lavoro-correlato. Art. 28 c.1-bis: aggiornamento della valutazione in caso di modifiche organizzative significative.
B7: Accordo Europeo SLC | C7: Accordo Quadro Europeo sullo Stress sul Lavoro dell'8 ottobre 2004, recepito in Italia con l'Accordo Interconfederale del 9 giugno 2008.
B8: Accordo Stato-Regioni 21/12/2011 | C8: Indicazioni per la corretta e completa applicazione dell'art. 28 c.1-bis del D.Lgs. 81/08 in materia di stress lavoro-correlato.
B9: Linee Guida INAIL 2017 | C9: "La metodologia per la valutazione e gestione del rischio stress lavoro-correlato" — Strumento Indicatore con 35 item su scala Likert 1-5 suddivisi in 4 aree: Contenuto del Lavoro, Contesto del Lavoro, Relazioni Interpersonali, Cambiamento Organizzativo.
B10: Monografia INAIL Aprile 2025 | C10: "Modulo contestualizzato al lavoro da remoto e all'innovazione tecnologica" — Integrazione con 27 item aggiuntivi: 10 Remote Work, 15 Technostress, 2 Work-Life Balance. Da utilizzare per gruppi omogenei con modalità Smart Working o con elevato uso di tecnologie ICT.
B12: STRUTTURA DEL FILE
B13: README_Istruzioni | C13: Il presente foglio. Riferimenti normativi, avvertenze e guida operativa.
B14: Configurazione | C14: Dati organizzazione, responsabili, soglie cut-off modificabili.
B15: Gruppi_Omogenei | C15: Anagrafica dei gruppi omogenei (reparto, mansione, turno, modalità lavoro).
B16: DataEntry_Standard | C16: Inserimento anonimo delle 35 risposte — Strumento Indicatore INAIL.
B17: DataEntry_SmartICT | C17: Inserimento anonimo dei 27 item aggiuntivi (solo gruppi Smart/ICT).
B18: Calcolo_Punteggi | C18: Inversione item, punteggi per sezione, totali, confronto con cut-off.
B19: Aggregazione_Gruppi | C19: Media, DS, distribuzione frequenze per ogni gruppo omogeneo.
B20: Classificazione_Rischio | C20: Fascia di rischio: Trascurabile / Moderato / Rilevante.
B21: Report_Risultati | C21: Tabelle e grafici aggregati pronti per il DVR.
B22: Privacy_Log | C22: Traccia anonima delle compilazioni (GDPR-compliant).
B24: GUIDA OPERATIVA
B25: Passo 1 — Configurazione | C25: Compilare il foglio 'Configurazione': nome azienda, data, responsabili, n. gruppi omogenei.
B26: Passo 2 — Gruppi Omogenei | C26: Definire ogni gruppo nel foglio 'Gruppi_Omogenei' (ID, reparto, mansione, turno, modalità lavoro).
B27: Passo 3 — Raccolta dati | C27: Per ogni compilatore (anonimo) inserire le risposte nel foglio 'DataEntry_Standard'. Per gruppi Smart/ICT, utilizzare anche 'DataEntry_SmartICT'.
B28: Passo 4 — Verifica | C28: Il foglio 'Calcolo_Punteggi' aggiorna automaticamente i risultati. Verificare l'assenza di celle vuote.
B29: Passo 5 — Report | C29: Consultare 'Classificazione_Rischio' e 'Report_Risultati' per la sintesi da inserire nel DVR.
B30: Passo 6 — Rivalutazione | C30: Il sistema genera alert automatico a 24/36 mesi. Ripetere la procedura ad ogni modifica organizzativa rilevante.
B32: AVVERTENZE PRIVACY (GDPR)
B33: Anonimato | C33: Non inserire MAI nome, cognome, codice fiscale o altri dati identificativi nei fogli DataEntry. Ogni compilazione è identificata esclusivamente dall'ID Gruppo Omogeneo.
B34: Elaborazione aggregata | C34: I risultati sono elaborati e visualizzati SOLO in forma aggregata per gruppo. Non è possibile risalire alle risposte del singolo lavoratore.
B35: Base giuridica | C35: Trattamento dati ex art. 9 par. 2 lett. b) GDPR (esecuzione obblighi di legge in materia di lavoro) e D.Lgs. 81/08. Informativa da fornire ai lavoratori prima della compilazione.
B36: Responsabilità | C36: La valutazione finale spetta al Datore di Lavoro con il supporto di RSPP e Medico Competente, previo coinvolgimento dell'RLS. Il presente strumento è ausiliario e non sostituisce la valutazione esperta.

Sheet Configurazione
B1: CONFIGURAZIONE VALUTAZIONE SLC
B2: DATI ORGANIZZAZIONE
B3: Nome Organizzazione / Azienda
B4: Sede / Unità Produttiva
B5: ATECO / Settore
B6: Numero totale dipendenti
B7: Data Valutazione | C7: 46158
B8: Data Rivalutazione (24 mesi) | C8: =IF(C6<>"",C6+730,"")
B9: Alert Rivalutazione | C9: =IF(C7<>"",IF(C7-TODAY()<=90,"⚠ RIVALUTAZIONE ENTRO 90 GG","OK"),"") -> ⚠ RIVALUTAZIONE ENTRO 90 GG
B11: TEAM DI VALUTAZIONE
B12: RSPP (Nome/Qualifica)
B13: Medico Competente
B14: RLS / RLST
B15: Consulente esterno (se presente)
B17: PARAMETRI VALUTAZIONE
B18: Numero Gruppi Omogenei | C18: 1
B19: Scala risposta | C19: Likert 1-5
B21: CUT-OFF RISCHIO — STRUMENTO STANDARD (35 item)
B22: Soglia Trascurabile (max) | C22: 2.3
B23: Soglia Moderato (max) | C23: 3
B24: (Oltre soglia Moderato → Rilevante)
B26: CUT-OFF RISCHIO — MODULO SMART/ICT (27 item aggiuntivi)
B27: Soglia Trascurabile (max) — Smart/ICT | C27: 2.5
B28: Soglia Moderato (max) — Smart/ICT | C28: 3.2
B30: NOTE MC (Medico Competente)

Sheet Gruppi_Omogenei
A1: ANAGRAFICA GRUPPI OMOGENEI
A2: ID_Gruppo | B2: Reparto / Ufficio | C2: Mansione Prevalente | D2: Turno | E2: Modalità Lavoro | F2: N. Componenti | G2: Smart/ICT Attivo | H2: Note
A3: GRP-01 | G3: =IF(OR(E3="Smart Working",E3="ICT Intensivo",E3="Smart+ICT"),"SÌ","NO") -> NO
A4: GRP-02 | G4: =IF(OR(E4="Smart Working",E4="ICT Intensivo",E4="Smart+ICT"),"SÌ","NO") -> NO
A5: GRP-03 | G5: =IF(OR(E5="Smart Working",E5="ICT Intensivo",E5="Smart+ICT"),"SÌ","NO") -> NO
A6: GRP-04 | G6: =IF(OR(E6="Smart Working",E6="ICT Intensivo",E6="Smart+ICT"),"SÌ","NO") -> NO
A7: GRP-05 | G7: =IF(OR(E7="Smart Working",E7="ICT Intensivo",E7="Smart+ICT"),"SÌ","NO") -> NO
A8: GRP-06 | G8: =IF(OR(E8="Smart Working",E8="ICT Intensivo",E8="Smart+ICT"),"SÌ","NO") -> NO
A9: GRP-07 | G9: =IF(OR(E9="Smart Working",E9="ICT Intensivo",E9="Smart+ICT"),"SÌ","NO") -> NO
A10: GRP-08 | G10: =IF(OR(E10="Smart Working",E10="ICT Intensivo",E10="Smart+ICT"),"SÌ","NO") -> NO
A11: GRP-09 | G11: =IF(OR(E11="Smart Working",E11="ICT Intensivo",E11="Smart+ICT"),"SÌ","NO") -> NO
A12: GRP-10 | G12: =IF(OR(E12="Smart Working",E12="ICT Intensivo",E12="Smart+ICT"),"SÌ","NO") -> NO
A13: GRP-11 | G13: =IF(OR(E13="Smart Working",E13="ICT Intensivo",E13="Smart+ICT"),"SÌ","NO") -> NO
A14: GRP-12 | G14: =IF(OR(E14="Smart Working",E14="ICT Intensivo",E14="Smart+ICT"),"SÌ","NO") -> NO
... A22: GRP-20 | G22: =IF(OR(E22="Smart Working",E22="ICT Intensivo",E22="Smart+ICT"),"SÌ","NO") -> NO

Sheet DataEntry_Standard
A1: INSERIMENTO DATI — STRUMENTO INDICATORE INAIL (35 ITEM) — DATI ANONIMI
A2: ID_Compilazione | B2: Data_Compilazione | C2: ID_Gruppo | D2: Item01 | E2: Item02 | F2: Item03 | G2: Item04 | H2: Item05 | I2: Item06 | J2: Item07 | K2: Item08 | L2: Item09 | M2: Item10 | N2: Item11 | O2: Item12 | P2: Item13 | Q2: Item14 | R2: Item15 | S2: Item16 | T2: Item17 | U2: Item18 | V2: Item19 | W2: Item20 | X2: Item21 | Y2: Item22 | Z2: Item23 | AA2: Item24 | AB2: Item25 | AC2: Item26 | AD2: Item27 | AE2: Item28 | AF2: Item29 | AG2: Item30 | AH2: Item31 | AI2: Item32 | AJ2: Item33 | AK2: Item34 | AL2: Item35
D3: Contenuto | E3: Contenuto | F3: Contenuto | G3: Contenuto | H3: Contenuto | I3: Contenuto | J3: Contenuto | K3: Contenuto | L3: Contenuto | M3: Contenuto | N3: Contesto | O3: Contesto | P3: Contesto | Q3: Contesto | R3: Contesto | S3: Contesto | T3: Contesto | U3: Contesto | V3: Contesto | W3: Relazioni | X3: Relazioni | Y3: Relazioni | Z3: Relazioni | AA3: Relazioni | AB3: Relazioni | AC3: Relazioni | AD3: Relazioni | AE3: Cambiamento | AF3: Cambiamento | AG3: Cambiamento | AH3: Cambiamento | AI3: Cambiamento | AJ3: Equilibrio | AK3: Equilibrio | AL3: Equilibrio
A4: ID anonimo | B4: Data (gg/mm/aa) | C4: ID Gruppo | D4: [D] Chiarezza del ruolo e dei compiti | E4: [R] Sovraccarico quantitativo (carico eccessivo) | F4: [R] Monotonia / ripetitività del lavoro | G4: [D] Controllo sul metodo di lavoro (autonomia) | H4: [R] Ritmi di lavoro imposti dall'esterno | I4: [D] Adeguatezza delle competenze richieste | J4: [D] Varietà dei compiti assegnati | K4: [D] Possibilità di sviluppo professionale | L4: [D] Significatività del lavoro svolto | M4: [D] Feedback sul lavoro ricevuto | N4: [D] Chiarezza degli obiettivi organizzativi | O4: [D] Partecipazione alle decisioni che riguardano il proprio lavoro | P4: [D] Comunicazione interna adeguata | Q4: [R] Ambiguità di ruolo (conflitti di competenza) | R4: [R] Conflitto di ruolo (richieste contraddittorie) | S4: [R] Responsabilità per il lavoro altrui | T4: [D] Supporto del responsabile diretto | U4: [D] Disponibilità di risorse adeguate | V4: [D] Riconoscimento dell'impegno profuso | W4: [D] Supporto dei colleghi | X4: [R] Conflittualità interpersonale | Y4: [R] Isolamento sociale o professionale | Z4: [D] Clima di lavoro complessivo | AA4: [R] Comportamenti scorretti (mobbing/molestie) | AB4: [D] Equità nel trattamento | AC4: [D] Collaborazione nel team | AD4: [D] Rispetto e cortesia | AE4: [D] Comunicazione sui cambiamenti organizzativi | AF4: [R] Gestione delle incertezze lavorative | AG4: [D] Coinvolgimento nei processi di cambiamento | AH4: [R] Adattabilità richiesta (flessibilità eccessiva) | AI4: [D] Supporto durante le transizioni organizzative | AJ4: [D] Orario di lavoro adeguato | AK4: [R] Interferenza lavoro-vita privata | AL4: [D] Rispetto dei periodi di riposo
A5: COMP-001
A6: COMP-002
A7: COMP-003
A8: COMP-004
A9: COMP-005
A10: COMP-006
A11: COMP-007
A12: COMP-008
A13: COMP-009
A14: COMP-010
A15: COMP-011
A16: COMP-012
... A54: COMP-050

Sheet DataEntry_SmartICT
A1: INSERIMENTO DATI — MODULO SMART/ICT INAIL 2025 (27 ITEM AGGIUNTIVI) — DATI ANONIMI
A2: ID_Compilazione | B2: Data_Compilazione | C2: ID_Gruppo | D2: ICT01 | E2: ICT02 | F2: ICT03 | G2: ICT04 | H2: ICT05 | I2: ICT06 | J2: ICT07 | K2: ICT08 | L2: ICT09 | M2: ICT10 | N2: ICT11 | O2: ICT12 | P2: ICT13 | Q2: ICT14 | R2: ICT15 | S2: ICT16 | T2: ICT17 | U2: ICT18 | V2: ICT19 | W2: ICT20 | X2: ICT21 | Y2: ICT22 | Z2: ICT23 | AA2: ICT24 | AB2: ICT25 | AC2: ICT26 | AD2: ICT27
D3: Remote Work | E3: Remote Work | F3: Remote Work | G3: Remote Work | H3: Remote Work | I3: Remote Work | J3: Remote Work | K3: Remote Work | L3: Remote Work | M3: Remote Work | N3: Technostress | O3: Technostress | P3: Technostress | Q3: Technostress | R3: Technostress | S3: Technostress | T3: Technostress | U3: Technostress | V3: Technostress | W3: Technostress | X3: Technostress | Y3: Technostress | Z3: Technostress | AA3: Technostress | AB3: Technostress | AC3: Work-Life | AD3: Work-Life
D4: [D] Adeguatezza della postazione di lavoro da remoto | E4: [D] Connettività e strumenti tecnologici disponibili | F4: [R] Difficoltà di comunicazione con il team a distanza | G4: [R] Percezione di isolamento professionale | H4: [D] Capacità di gestione autonoma del tempo | I4: [D] Chiarezza degli obiettivi in modalità remota | J4: [R] Interferenza con la sfera domestica | K4: [D] Supporto del responsabile in modalità remota | L4: [R] Difficoltà di disconnessione al termine del lavoro | M4: [D] Equità percepita rispetto ai colleghi in presenza | N4: [R] Sovraccarico informativo (information overload) | O4: [R] Ansia da prestazione tecnologica | P4: [R] Difficoltà di apprendimento di nuovi software/sistemi | Q4: [R] Interruzioni frequenti causate da notifiche/alert | R4: [R] Paura di obsolescenza delle competenze digitali | S4: [R] Monitoraggio elettronico percepito come invasivo | T4: [R] Affaticamento visivo/posturale da uso prolungato ICT | U4: [R] Difficoltà a staccare dai dispositivi digitali | V4: [D] Efficacia percepita nell'uso delle tecnologie | W4: [D] Aggiornamento tecnologico adeguato alle esigenze | X4: [D] Supporto tecnico disponibile e tempestivo | Y4: [D] Trasparenza algoritmi e sistemi di supporto decisionale | Z4: [R] Preoccupazione per automazione/sostituzione AI | AA4: [R] Dipendenza percepita da sistemi automatizzati | AB4: [D] Fiducia complessiva nella tecnologia aziendale | AC4: [R] Confusione tra spazio domestico e spazio lavorativo | AD4: [D] Rispetto dei limiti orario in modalità Smart/ICT
A5: COMP-001
A6: COMP-002
A7: COMP-003
A8: COMP-004
A9: COMP-005
A10: COMP-006
A11: COMP-007
A12: COMP-008
A13: COMP-009
A14: COMP-010
A15: COMP-011
A16: COMP-012
... A54: COMP-050

Sheet Calcolo_Punteggi
A1: CALCOLO PUNTEGGI — STRUMENTO INDICATORE INAIL
A2: ID_Compilazione | B2: ID_Gruppo | C2: Punteggio_Contenuto | D2: Punteggio_Contesto | E2: Punteggio_Relazioni | F2: Punteggio_Cambiamento | G2: Punteggio_Equilibrio | H2: Totale_Standard | I2: N_Item_Critici | J2: Punteggio_SmartICT | K2: Totale_Combinato | L2: Fascia_Rischio_Std | M2: Fascia_Rischio_ICT
A3: =DataEntry_Standard!A5 -> COMP-001 | B3: =DataEntry_Standard!C5 -> 0 | C3: =IF(DataEntry_Standard!D5<>"",DataEntry_Standard!D5,0)+IF(DataEntry_Standard!E5<>"",6-DataEntry_Standard!E5,0)+IF(DataEntry_Standard!F5<>"",6-DataEntry_Standard!F5,0)+IF(DataEntry_Standard!G5<>"",DataEntry_Standard!G5,0)+IF(DataEntry_Standard!H5<>"",6-DataEntry_Standard!H5,0)+IF(DataEntry_Standard!I5<>"",DataEntry_Standard!I5,0)+IF(DataEntry_Standard!J5<>"",DataEntry_Standard!J5,0)+IF(DataEntry_Standard!K5<>"",DataEntry_Standard!K5,0)+IF(DataEntry_Standard!L5<>"",DataEntry_Standard!L5,0)+IF(DataEntry_Standard!M5<>"",DataEntry_Standard!M5,0) -> 0 | D3: =IF(DataEntry_Standard!N5<>"",DataEntry_Standard!N5,0)+IF(DataEntry_Standard!O5<>"",DataEntry_Standard!O5,0)+IF(DataEntry_Standard!P5<>"",DataEntry_Standard!P5,0)+IF(DataEntry_Standard!Q5<>"",6-DataEntry_Standard!Q5,0)+IF(DataEntry_Standard!R5<>"",6-DataEntry_Standard!R5,0)+IF(DataEntry_Standard!S5<>"",6-DataEntry_Standard!S5,0)+IF(DataEntry_Standard!T5<>"",DataEntry_Standard!T5,0)+IF(DataEntry_Standard!U5<>"",DataEntry_Standard!U5,0)+IF(DataEntry_Standard!V5<>"",DataEntry_Standard!V5,0) -> 0 | E3: =IF(DataEntry_Standard!W5<>"",DataEntry_Standard!W5,0)+IF(DataEntry_Standard!X5<>"",6-DataEntry_Standard!X5,0)+IF(DataEntry_Standard!Y5<>"",6-DataEntry_Standard!Y5,0)+IF(DataEntry_Standard!Z5<>"",DataEntry_Standard!Z5,0)+IF(DataEntry_Standard!AA5<>"",6-DataEntry_Standard!AA5,0)+IF(DataEntry_Standard!AB5<>"",DataEntry_Standard!AB5,0)+IF(DataEntry_Standard!AC5<>"",DataEntry_Standard!AC5,0)+IF(DataEntry_Standard!AD5<>"",DataEntry_Standard!AD5,0) -> 0 | F3: =IF(DataEntry_Standard!AE5<>"",DataEntry_Standard!AE5,0)+IF(DataEntry_Standard!AF5<>"",DataEntry_Standard!AF5,0)+IF(DataEntry_Standard!AG5<>"",6-DataEntry_Standard!AG5,0)+IF(DataEntry_Standard!AH5<>"",DataEntry_Standard!AH5,0)+IF(DataEntry_Standard!AI5<>"",6-DataEntry_Standard!AI5,0) -> 0 | G3: =IF(DataEntry_Standard!AJ5<>"",DataEntry_Standard!AJ5,0)+IF(DataEntry_Standard!AK5<>"",6-DataEntry_Standard!AK5,0)+IF(DataEntry_Standard!AL5<>"",DataEntry_Standard!AL5,0) -> 0 | H3: =IF(A3<>"",C3+D3+E3+F3+G3,"") -> 0 | I3: =IF(DataEntry_Standard!D5>=4,1,0)+IF(DataEntry_Standard!G5>=4,1,0)+IF(DataEntry_Standard!I5>=4,1,0)+IF(DataEntry_Standard!J5>=4,1,0)+IF(DataEntry_Standard!K5>=4,1,0)+IF(DataEntry_Standard!L5>=4,1,0)+IF(DataEntry_Standard!M5>=4,1,0)+IF(DataEntry_Standard!N5>=4,1,0)+IF(DataEntry_Standard!O5>=4,1,0)+IF(DataEntry_Standard!P5>=4,1,0)+IF(DataEntry_Standard!T5>=4,1,0)+IF(DataEntry_Standard!U5>=4,1,0)+IF(DataEntry_Standard!V5>=4,1,0)+IF(DataEntry_Standard!W5>=4,1,0)+IF(DataEntry_Standard!Z5>=4,1,0)+IF(DataEntry_Standard!AB5>=4,1,0)+IF(DataEntry_Standard!AC5>=4,1,0)+IF(DataEntry_Standard!AD5>=4,1,0)+IF(DataEntry_Standard!AE5>=4,1,0)+IF(DataEntry_Standard!AF5>=4,1,0)+IF(DataEntry_Standard!AH5>=4,1,0)+IF(DataEntry_Standard!AJ5>=4,1,0)+IF(DataEntry_Standard!AL5>=4,1,0)+IF(DataEntry_Standard!AI5<=2,1,0)+IF(DataEntry_Standard!E5<=2,1,0)+IF(DataEntry_Standard!F5<=2,1,0)+IF(DataEntry_Standard!AK5<=2,1,0)+IF(DataEntry_Standard!H5<=2,1,0)+IF(DataEntry_Standard!Q5<=2,1,0)+IF(DataEntry_Standard!R5<=2,1,0)+IF(DataEntry_Standard!S5<=2,1,0)+IF(DataEntry_Standard!X5<=2,1,0)+IF(DataEntry_Standard!Y5<=2,1,0)+IF(DataEntry_Standard!AA5<=2,1,0)+IF(DataEntry_Standard!AG5<=2,1,0) -> 12 | J3: =IF(DataEntry_SmartICT!D5<>"",DataEntry_SmartICT!D5,0)+IF(DataEntry_SmartICT!E5<>"",DataEntry_SmartICT!E5,0)+IF(DataEntry_SmartICT!F5<>"",6-DataEntry_SmartICT!F5,0)+IF(DataEntry_SmartICT!G5<>"",6-DataEntry_SmartICT!G5,0)+IF(DataEntry_SmartICT!H5<>"",DataEntry_SmartICT!H5,0)+IF(DataEntry_SmartICT!I5<>"",DataEntry_SmartICT!I5,0)+IF(DataEntry_SmartICT!J5<>"",6-DataEntry_SmartICT!J5,0)+IF(DataEntry_SmartICT!K5<>"",DataEntry_SmartICT!K5,0)+IF(DataEntry_SmartICT!L5<>"",6-DataEntry_SmartICT!L5,0)+IF(DataEntry_SmartICT!M5<>"",DataEntry_SmartICT!M5,0)+IF(DataEntry_SmartICT!N5<>"",6-DataEntry_SmartICT!N5,0)+IF(DataEntry_SmartICT!O5<>"",6-DataEntry_SmartICT!O5,0)+IF(DataEntry_SmartICT!P5<>"",6-DataEntry_SmartICT!P5,0)+IF(DataEntry_SmartICT!Q5<>"",6-DataEntry_SmartICT!Q5,0)+IF(DataEntry_SmartICT!R5<>"",6-DataEntry_SmartICT!R5,0)+IF(DataEntry_SmartICT!S5<>"",6-DataEntry_SmartICT!S5,0)+IF(DataEntry_SmartICT!T5<>"",6-DataEntry_SmartICT!T5,0)+IF(DataEntry_SmartICT!U5<>"",6-DataEntry_SmartICT!U5,0)+IF(DataEntry_SmartICT!V5<>"",DataEntry_SmartICT!V5,0)+IF(DataEntry_SmartICT!W5<>"",DataEntry_SmartICT!W5,0)+IF(DataEntry_SmartICT!X5<>"",DataEntry_SmartICT!X5,0)+IF(DataEntry_SmartICT!Y5<>"",6-DataEntry_SmartICT!Y5,0)+IF(DataEntry_SmartICT!Z5<>"",6-DataEntry_SmartICT!Z5,0)+IF(DataEntry_SmartICT!AA5<>"",DataEntry_SmartICT!AA5,0)+IF(DataEntry_SmartICT!AB5<>"",DataEntry_SmartICT!AB5,0)+IF(DataEntry_SmartICT!AC5<>"",6-DataEntry_SmartICT!AC5,0)+IF(DataEntry_SmartICT!AD5<>"",DataEntry_SmartICT!AD5,0) -> 0 | K3: =IF(H3<>"",IFERROR(H3+J3,H3),"") -> 0 | L3: =IF(H3="","",IF(H3/35<=Configurazione!C21,"Trascurabile",IF(H3/35<=Configurazione!C22,"Moderato","Rilevante"))) -> Trascurabile | M3: =IF(J3=0,"N/A",IF(J3/27<=Configurazione!C26,"Trascurabile",IF(J3/27<=Configurazione!C27,"Moderato","Rilevante"))) -> N/A
A4: =DataEntry_Standard!A6 -> COMP-002 | B4: =DataEntry_Standard!C6 -> 0 | C4: =IF(DataEntry_Standard!D6<>"",DataEntry_Standard!D6,0)+IF(DataEntry_Standard!E6<>"",6-DataEntry_Standard!E6,0)+IF(DataEntry_Standard!F6<>"",6-DataEntry_Standard!F6,0)+IF(DataEntry_Standard!G6<>"",DataEntry_Standard!G6,0)+IF(DataEntry_Standard!H6<>"",6-DataEntry_Standard!H6,0)+IF(DataEntry_Standard!I6<>"",DataEntry_Standard!I6,0)+IF(DataEntry_Standard!J6<>"",DataEntry_Standard!J6,0)+IF(DataEntry_Standard!K6<>"",DataEntry_Standard!K6,0)+IF(DataEntry_Standard!L6<>"",DataEntry_Standard!L6,0)+IF(DataEntry_Standard!M6<>"",DataEntry_Standard!M6,0) -> 0 | D4: =IF(DataEntry_Standard!N6<>"",DataEntry_Standard!N6,0)+IF(DataEntry_Standard!O6<>"",DataEntry_Standard!O6,0)+IF(DataEntry_Standard!P6<>"",DataEntry_Standard!P6,0)+IF(DataEntry_Standard!Q6<>"",6-DataEntry_Standard!Q6,0)+IF(DataEntry_Standard!R6<>"",6-DataEntry_Standard!R6,0)+IF(DataEntry_Standard!S6<>"",6-DataEntry_Standard!S6,0)+IF(DataEntry_Standard!T6<>"",DataEntry_Standard!T6,0)+IF(DataEntry_Standard!U6<>"",DataEntry_Standard!U6,0)+IF(DataEntry_Standard!V6<>"",DataEntry_Standard!V6,0) -> 0 | E4: =IF(DataEntry_Standard!W6<>"",DataEntry_Standard!W6,0)+IF(DataEntry_Standard!X6<>"",6-DataEntry_Standard!X6,0)+IF(DataEntry_Standard!Y6<>"",6-DataEntry_Standard!Y6,0)+IF(DataEntry_Standard!Z6<>"",DataEntry_Standard!Z6,0)+IF(DataEntry_Standard!AA6<>"",6-DataEntry_Standard!AA6,0)+IF(DataEntry_Standard!AB6<>"",DataEntry_Standard!AB6,0)+IF(DataEntry_Standard!AC6<>"",DataEntry_Standard!AC6,0)+IF(DataEntry_Standard!AD6<>"",DataEntry_Standard!AD6,0) -> 0 | F4: =IF(DataEntry_Standard!AE6<>"",DataEntry_Standard!AE6,0)+IF(DataEntry_Standard!AF6<>"",DataEntry_Standard!AF6,0)+IF(DataEntry_Standard!AG6<>"",6-DataEntry_Standard!AG6,0)+IF(DataEntry_Standard!AH6<>"",DataEntry_Standard!AH6,0)+IF(DataEntry_Standard!AI6<>"",6-DataEntry_Standard!AI6,0) -> 0 | G4: =IF(DataEntry_Standard!AJ6<>"",DataEntry_Standard!AJ6,0)+IF(DataEntry_Standard!AK6<>"",6-DataEntry_Standard!AK6,0)+IF(DataEntry_Standard!AL6<>"",DataEntry_Standard!AL6,0) -> 0 | H4: =IF(A4<>"",C4+D4+E4+F4+G4,"") -> 0 | I4: =IF(DataEntry_Standard!D6>=4,1,0)+IF(DataEntry_Standard!G6>=4,1,0)+IF(DataEntry_Standard!I6>=4,1,0)+IF(DataEntry_Standard!J6>=4,1,0)+IF(DataEntry_Standard!K6>=4,1,0)+IF(DataEntry_Standard!L6>=4,1,0)+IF(DataEntry_Standard!M6>=4,1,0)+IF(DataEntry_Standard!N6>=4,1,0)+IF(DataEntry_Standard!O6>=4,1,0)+IF(DataEntry_Standard!P6>=4,1,0)+IF(DataEntry_Standard!T6>=4,1,0)+IF(DataEntry_Standard!U6>=4,1,0)+IF(DataEntry_Standard!V6>=4,1,0)+IF(DataEntry_Standard!W6>=4,1,0)+IF(DataEntry_Standard!Z6>=4,1,0)+IF(DataEntry_Standard!AB6>=4,1,0)+IF(DataEntry_Standard!AC6>=4,1,0)+IF(DataEntry_Standard!AD6>=4,1,0)+IF(DataEntry_Standard!AE6>=4,1,0)+IF(DataEntry_Standard!AF6>=4,1,0)+IF(DataEntry_Standard!AH6>=4,1,0)+IF(DataEntry_Standard!AJ6>=4,1,0)+IF(DataEntry_Standard!AL6>=4,1,0)+IF(DataEntry_Standard!AI6<=2,1,0)+IF(DataEntry_Standard!E6<=2,1,0)+IF(DataEntry_Standard!F6<=2,1,0)+IF(DataEntry_Standard!AK6<=2,1,0)+IF(DataEntry_Standard!H6<=2,1,0)+IF(DataEntry_Standard!Q6<=2,1,0)+IF(DataEntry_Standard!R6<=2,1,0)+IF(DataEntry_Standard!S6<=2,1,0)+IF(DataEntry_Standard!X6<=2,1,0)+IF(DataEntry_Standard!Y6<=2,1,0)+IF(DataEntry_Standard!AA6<=2,1,0)+IF(DataEntry_Standard!AG6<=2,1,0) -> 12 | J4: =IF(DataEntry_SmartICT!D6<>"",DataEntry_SmartICT!D6,0)+IF(DataEntry_SmartICT!E6<>"",DataEntry_SmartICT!E6,0)+IF(DataEntry_SmartICT!F6<>"",6-DataEntry_SmartICT!F6,0)+IF(DataEntry_SmartICT!G6<>"",6-DataEntry_SmartICT!G6,0)+IF(DataEntry_SmartICT!H6<>"",DataEntry_SmartICT!H6,0)+IF(DataEntry_SmartICT!I6<>"",DataEntry_SmartICT!I6,0)+IF(DataEntry_SmartICT!J6<>"",6-DataEntry_SmartICT!J6,0)+IF(DataEntry_SmartICT!K6<>"",DataEntry_SmartICT!K6,0)+IF(DataEntry_SmartICT!L6<>"",6-DataEntry_SmartICT!L6,0)+IF(DataEntry_SmartICT!M6<>"",DataEntry_SmartICT!M6,0)+IF(DataEntry_SmartICT!N6<>"",6-DataEntry_SmartICT!N6,0)+IF(DataEntry_SmartICT!O6<>"",6-DataEntry_SmartICT!O6,0)+IF(DataEntry_SmartICT!P6<>"",6-DataEntry_SmartICT!P6,0)+IF(DataEntry_SmartICT!Q6<>"",6-DataEntry_SmartICT!Q6,0)+IF(DataEntry_SmartICT!R6<>"",6-DataEntry_SmartICT!R6,0)+IF(DataEntry_SmartICT!S6<>"",6-DataEntry_SmartICT!S6,0)+IF(DataEntry_SmartICT!T6<>"",6-DataEntry_SmartICT!T6,0)+IF(DataEntry_SmartICT!U6<>"",6-DataEntry_SmartICT!U6,0)+IF(DataEntry_SmartICT!V6<>"",DataEntry_SmartICT!V6,0)+IF(DataEntry_SmartICT!W6<>"",DataEntry_SmartICT!W6,0)+IF(DataEntry_SmartICT!X6<>"",DataEntry_SmartICT!X6,0)+IF(DataEntry_SmartICT!Y6<>"",6-DataEntry_SmartICT!Y6,0)+IF(DataEntry_SmartICT!Z6<>"",6-DataEntry_SmartICT!Z6,0)+IF(DataEntry_SmartICT!AA6<>"",DataEntry_SmartICT!AA6,0)+IF(DataEntry_SmartICT!AB6<>"",DataEntry_SmartICT!AB6,0)+IF(DataEntry_SmartICT!AC6<>"",6-DataEntry_SmartICT!AC6,0)+IF(DataEntry_SmartICT!AD6<>"",DataEntry_SmartICT!AD6,0) -> 0 | K4: =IF(H4<>"",IFERROR(H4+J4,H4),"") -> 0 | L4: =IF(H4="","",IF(H4/35<=Configurazione!C21,"Trascurabile",IF(H4/35<=Configurazione!C22,"Moderato","Rilevante"))) -> Trascurabile | M4: =IF(J4=0,"N/A",IF(J4/27<=Configurazione!C26,"Trascurabile",IF(J4/27<=Configurazione!C27,"Moderato","Rilevante"))) -> N/A
A5: =DataEntry_Standard!A7 -> COMP-003 | B5: =DataEntry_Standard!C7 -> 0 | C5: =IF(DataEntry_Standard!D7<>"",DataEntry_Standard!D7,0)+IF(DataEntry_Standard!E7<>"",6-DataEntry_Standard!E7,0)+IF(DataEntry_Standard!F7<>"",6-DataEntry_Standard!F7,0)+IF(DataEntry_Standard!G7<>"",DataEntry_Standard!G7,0)+IF(DataEntry_Standard!H7<>"",6-DataEntry_Standard!H7,0)+IF(DataEntry_Standard!I7<>"",DataEntry_Standard!I7,0)+IF(DataEntry_Standard!J7<>"",DataEntry_Standard!J7,0)+IF(DataEntry_Standard!K7<>"",DataEntry_Standard!K7,0)+IF(DataEntry_Standard!L7<>"",DataEntry_Standard!L7,0)+IF(DataEntry_Standard!M7<>"",DataEntry_Standard!M7,0) -> 0 | D5: =IF(DataEntry_Standard!N7<>"",DataEntry_Standard!N7,0)+IF(DataEntry_Standard!O7<>"",DataEntry_Standard!O7,0)+IF(DataEntry_Standard!P7<>"",DataEntry_Standard!P7,0)+IF(DataEntry_Standard!Q7<>"",6-DataEntry_Standard!Q7,0)+IF(DataEntry_Standard!R7<>"",6-DataEntry_Standard!R7,0)+IF(DataEntry_Standard!S7<>"",6-DataEntry_Standard!S7,0)+IF(DataEntry_Standard!T7<>"",DataEntry_Standard!T7,0)+IF(DataEntry_Standard!U7<>"",DataEntry_Standard!U7,0)+IF(DataEntry_Standard!V7<>"",DataEntry_Standard!V7,0) -> 0 | E5: =IF(DataEntry_Standard!W7<>"",DataEntry_Standard!W7,0)+IF(DataEntry_Standard!X7<>"",6-DataEntry_Standard!X7,0)+IF(DataEntry_Standard!Y7<>"",6-DataEntry_Standard!Y7,0)+IF(DataEntry_Standard!Z7<>"",DataEntry_Standard!Z7,0)+IF(DataEntry_Standard!AA7<>"",6-DataEntry_Standard!AA7,0)+IF(DataEntry_Standard!AB7<>"",DataEntry_Standard!AB7,0)+IF(DataEntry_Standard!AC7<>"",DataEntry_Standard!AC7,0)+IF(DataEntry_Standard!AD7<>"",DataEntry_Standard!AD7,0) -> 0 | F5: =IF(DataEntry_Standard!AE7<>"",DataEntry_Standard!AE7,0)+IF(DataEntry_Standard!AF7<>"",DataEntry_Standard!AF7,0)+IF(DataEntry_Standard!AG7<>"",6-DataEntry_Standard!AG7,0)+IF(DataEntry_Standard!AH7<>"",DataEntry_Standard!AH7,0)+IF(DataEntry_Standard!AI7<>"",6-DataEntry_Standard!AI7,0) -> 0 | G5: =IF(DataEntry_Standard!AJ7<>"",DataEntry_Standard!AJ7,0)+IF(DataEntry_Standard!AK7<>"",6-DataEntry_Standard!AK7,0)+IF(DataEntry_Standard!AL7<>"",DataEntry_Standard!AL7,0) -> 0 | H5: =IF(A5<>"",C5+D5+E5+F5+G5,"") -> 0 | I5: =IF(DataEntry_Standard!D7>=4,1,0)+IF(DataEntry_Standard!G7>=4,1,0)+IF(DataEntry_Standard!I7>=4,1,0)+IF(DataEntry_Standard!J7>=4,1,0)+IF(DataEntry_Standard!K7>=4,1,0)+IF(DataEntry_Standard!L7>=4,1,0)+IF(DataEntry_Standard!M7>=4,1,0)+IF(DataEntry_Standard!N7>=4,1,0)+IF(DataEntry_Standard!O7>=4,1,0)+IF(DataEntry_Standard!P7>=4,1,0)+IF(DataEntry_Standard!T7>=4,1,0)+IF(DataEntry_Standard!U7>=4,1,0)+IF(DataEntry_Standard!V7>=4,1,0)+IF(DataEntry_Standard!W7>=4,1,0)+IF(DataEntry_Standard!Z7>=4,1,0)+IF(DataEntry_Standard!AB7>=4,1,0)+IF(DataEntry_Standard!AC7>=4,1,0)+IF(DataEntry_Standard!AD7>=4,1,0)+IF(DataEntry_Standard!AE7>=4,1,0)+IF(DataEntry_Standard!AF7>=4,1,0)+IF(DataEntry_Standard!AH7>=4,1,0)+IF(DataEntry_Standard!AJ7>=4,1,0)+IF(DataEntry_Standard!AL7>=4,1,0)+IF(DataEntry_Standard!AI7<=2,1,0)+IF(DataEntry_Standard!E7<=2,1,0)+IF(DataEntry_Standard!F7<=2,1,0)+IF(DataEntry_Standard!AK7<=2,1,0)+IF(DataEntry_Standard!H7<=2,1,0)+IF(DataEntry_Standard!Q7<=2,1,0)+IF(DataEntry_Standard!R7<=2,1,0)+IF(DataEntry_Standard!S7<=2,1,0)+IF(DataEntry_Standard!X7<=2,1,0)+IF(DataEntry_Standard!Y7<=2,1,0)+IF(DataEntry_Standard!AA7<=2,1,0)+IF(DataEntry_Standard!AG7<=2,1,0) -> 12 | J5: =IF(DataEntry_SmartICT!D7<>"",DataEntry_SmartICT!D7,0)+IF(DataEntry_SmartICT!E7<>"",DataEntry_SmartICT!E7,0)+IF(DataEntry_SmartICT!F7<>"",6-DataEntry_SmartICT!F7,0)+IF(DataEntry_SmartICT!G7<>"",6-DataEntry_SmartICT!G7,0)+IF(DataEntry_SmartICT!H7<>"",DataEntry_SmartICT!H7,0)+IF(DataEntry_SmartICT!I7<>"",DataEntry_SmartICT!I7,0)+IF(DataEntry_SmartICT!J7<>"",6-DataEntry_SmartICT!J7,0)+IF(DataEntry_SmartICT!K7<>"",DataEntry_SmartICT!K7,0)+IF(DataEntry_SmartICT!L7<>"",6-DataEntry_SmartICT!L7,0)+IF(DataEntry_SmartICT!M7<>"",DataEntry_SmartICT!M7,0)+IF(DataEntry_SmartICT!N7<>"",6-DataEntry_SmartICT!N7,0)+IF(DataEntry_SmartICT!O7<>"",6-DataEntry_SmartICT!O7,0)+IF(DataEntry_SmartICT!P7<>"",6-DataEntry_SmartICT!P7,0)+IF(DataEntry_SmartICT!Q7<>"",6-DataEntry_SmartICT!Q7,0)+IF(DataEntry_SmartICT!R7<>"",6-DataEntry_SmartICT!R7,0)+IF(DataEntry_SmartICT!S7<>"",6-DataEntry_SmartICT!S7,0)+IF(DataEntry_SmartICT!T7<>"",6-DataEntry_SmartICT!T7,0)+IF(DataEntry_SmartICT!U7<>"",6-DataEntry_SmartICT!U7,0)+IF(DataEntry_SmartICT!V7<>"",DataEntry_SmartICT!V7,0)+IF(DataEntry_SmartICT!W7<>"",DataEntry_SmartICT!W7,0)+IF(DataEntry_SmartICT!X7<>"",DataEntry_SmartICT!X7,0)+IF(DataEntry_SmartICT!Y7<>"",6-DataEntry_SmartICT!Y7,0)+IF(DataEntry_SmartICT!Z7<>"",6-DataEntry_SmartICT!Z7,0)+IF(DataEntry_SmartICT!AA7<>"",DataEntry_SmartICT!AA7,0)+IF(DataEntry_SmartICT!AB7<>"",DataEntry_SmartICT!AB7,0)+IF(DataEntry_SmartICT!AC7<>"",6-DataEntry_SmartICT!AC7,0)+IF(DataEntry_SmartICT!AD7<>"",DataEntry_SmartICT!AD7,0) -> 0 | K5: =IF(H5<>"",IFERROR(H5+J5,H5),"") -> 0 | L5: =IF(H5="","",IF(H5/35<=Configurazione!C21,"Trascurabile",IF(H5/35<=Configurazione!C22,"Moderato","Rilevante"))) -> Trascurabile | M5: =IF(J5=0,"N/A",IF(J5/27<=Configurazione!C26,"Trascurabile",IF(J5/27<=Configurazione!C27,"Moderato","Rilevante"))) -> N/A
A6: =DataEntry_Standard!A8 -> COMP-004 | B6: =DataEntry_Standard!C8 -> 0 | C6: =IF(DataEntry_Standard!D8<>"",DataEntry_Standard!D8,0)+IF(DataEntry_Standard!E8<>"",6-DataEntry_Standard!E8,0)+IF(DataEntry_Standard!F8<>"",6-DataEntry_Standard!F8,0)+IF(DataEntry_Standard!G8<>"",DataEntry_Standard!G8,0)+IF(DataEntry_Standard!H8<>"",6-DataEntry_Standard!H8,0)+IF(DataEntry_Standard!I8<>"",DataEntry_Standard!I8,0)+IF(DataEntry_Standard!J8<>"",DataEntry_Standard!J8,0)+IF(DataEntry_Standard!K8<>"",DataEntry_Standard!K8,0)+IF(DataEntry_Standard!L8<>"",DataEntry_Standard!L8,0)+IF(DataEntry_Standard!M8<>"",DataEntry_Standard!M8,0) -> 0 | D6: =IF(DataEntry_Standard!N8<>"",DataEntry_Standard!N8,0)+IF(DataEntry_Standard!O8<>"",DataEntry_Standard!O8,0)+IF(DataEntry_Standard!P8<>"",DataEntry_Standard!P8,0)+IF(DataEntry_Standard!Q8<>"",6-DataEntry_Standard!Q8,0)+IF(DataEntry_Standard!R8<>"",6-DataEntry_Standard!R8,0)+IF(DataEntry_Standard!S8<>"",6-DataEntry_Standard!S8,0)+IF(DataEntry_Standard!T8<>"",DataEntry_Standard!T8,0)+IF(DataEntry_Standard!U8<>"",DataEntry_Standard!U8,0)+IF(DataEntry_Standard!V8<>"",DataEntry_Standard!V8,0) -> 0 | E6: =IF(DataEntry_Standard!W8<>"",DataEntry_Standard!W8,0)+IF(DataEntry_Standard!X8<>"",6-DataEntry_Standard!X8,0)+IF(DataEntry_Standard!Y8<>"",6-DataEntry_Standard!Y8,0)+IF(DataEntry_Standard!Z8<>"",DataEntry_Standard!Z8,0)+IF(DataEntry_Standard!AA8<>"",6-DataEntry_Standard!AA8,0)+IF(DataEntry_Standard!AB8<>"",DataEntry_Standard!AB8,0)+IF(DataEntry_Standard!AC8<>"",DataEntry_Standard!AC8,0)+IF(DataEntry_Standard!AD8<>"",DataEntry_Standard!AD8,0) -> 0 | F6: =IF(DataEntry_Standard!AE8<>"",DataEntry_Standard!AE8,0)+IF(DataEntry_Standard!AF8<>"",DataEntry_Standard!AF8,0)+IF(DataEntry_Standard!AG8<>"",6-DataEntry_Standard!AG8,0)+IF(DataEntry_Standard!AH8<>"",DataEntry_Standard!AH8,0)+IF(DataEntry_Standard!AI8<>"",6-DataEntry_Standard!AI8,0) -> 0 | G6: =IF(DataEntry_Standard!AJ8<>"",DataEntry_Standard!AJ8,0)+IF(DataEntry_Standard!AK8<>"",6-DataEntry_Standard!AK8,0)+IF(DataEntry_Standard!AL8<>"",DataEntry_Standard!AL8,0) -> 0 | H6: =IF(A6<>"",C6+D6+E6+F6+G6,"") -> 0 | I6: =IF(DataEntry_Standard!D8>=4,1,0)+IF(DataEntry_Standard!G8>=4,1,0)+IF(DataEntry_Standard!I8>=4,1,0)+IF(DataEntry_Standard!J8>=4,1,0)+IF(DataEntry_Standard!K8>=4,1,0)+IF(DataEntry_Standard!L8>=4,1,0)+IF(DataEntry_Standard!M8>=4,1,0)+IF(DataEntry_Standard!N8>=4,1,0)+IF(DataEntry_Standard!O8>=4,1,0)+IF(DataEntry_Standard!P8>=4,1,0)+IF(DataEntry_Standard!T8>=4,1,0)+IF(DataEntry_Standard!U8>=4,1,0)+IF(DataEntry_Standard!V8>=4,1,0)+IF(DataEntry_Standard!W8>=4,1,0)+IF(DataEntry_Standard!Z8>=4,1,0)+IF(DataEntry_Standard!AB8>=4,1,0)+IF(DataEntry_Standard!AC8>=4,1,0)+IF(DataEntry_Standard!AD8>=4,1,0)+IF(DataEntry_Standard!AE8>=4,1,0)+IF(DataEntry_Standard!AF8>=4,1,0)+IF(DataEntry_Standard!AH8>=4,1,0)+IF(DataEntry_Standard!AJ8>=4,1,0)+IF(DataEntry_Standard!AL8>=4,1,0)+IF(DataEntry_Standard!AI8<=2,1,0)+IF(DataEntry_Standard!E8<=2,1,0)+IF(DataEntry_Standard!F8<=2,1,0)+IF(DataEntry_Standard!AK8<=2,1,0)+IF(DataEntry_Standard!H8<=2,1,0)+IF(DataEntry_Standard!Q8<=2,1,0)+IF(DataEntry_Standard!R8<=2,1,0)+IF(DataEntry_Standard!S8<=2,1,0)+IF(DataEntry_Standard!X8<=2,1,0)+IF(DataEntry_Standard!Y8<=2,1,0)+IF(DataEntry_Standard!AA8<=2,1,0)+IF(DataEntry_Standard!AG8<=2,1,0) -> 12 | J6: =IF(DataEntry_SmartICT!D8<>"",DataEntry_SmartICT!D8,0)+IF(DataEntry_SmartICT!E8<>"",DataEntry_SmartICT!E8,0)+IF(DataEntry_SmartICT!F8<>"",6-DataEntry_SmartICT!F8,0)+IF(DataEntry_SmartICT!G8<>"",6-DataEntry_SmartICT!G8,0)+IF(DataEntry_SmartICT!H8<>"",DataEntry_SmartICT!H8,0)+IF(DataEntry_SmartICT!I8<>"",DataEntry_SmartICT!I8,0)+IF(DataEntry_SmartICT!J8<>"",6-DataEntry_SmartICT!J8,0)+IF(DataEntry_SmartICT!K8<>"",DataEntry_SmartICT!K8,0)+IF(DataEntry_SmartICT!L8<>"",6-DataEntry_SmartICT!L8,0)+IF(DataEntry_SmartICT!M8<>"",DataEntry_SmartICT!M8,0)+IF(DataEntry_SmartICT!N8<>"",6-DataEntry_SmartICT!N8,0)+IF(DataEntry_SmartICT!O8<>"",6-DataEntry_SmartICT!O8,0)+IF(DataEntry_SmartICT!P8<>"",6-DataEntry_SmartICT!P8,0)+IF(DataEntry_SmartICT!Q8<>"",6-DataEntry_SmartICT!Q8,0)+IF(DataEntry_SmartICT!R8<>"",6-DataEntry_SmartICT!R8,0)+IF(DataEntry_SmartICT!S8<>"",6-DataEntry_SmartICT!S8,0)+IF(DataEntry_SmartICT!T8<>"",6-DataEntry_SmartICT!T8,0)+IF(DataEntry_SmartICT!U8<>"",6-DataEntry_SmartICT!U8,0)+IF(DataEntry_SmartICT!V8<>"",DataEntry_SmartICT!V8,0)+IF(DataEntry_SmartICT!W8<>"",DataEntry_SmartICT!W8,0)+IF(DataEntry_SmartICT!X8<>"",DataEntry_SmartICT!X8,0)+IF(DataEntry_SmartICT!Y8<>"",6-DataEntry_SmartICT!Y8,0)+IF(DataEntry_SmartICT!Z8<>"",6-DataEntry_SmartICT!Z8,0)+IF(DataEntry_SmartICT!AA8<>"",DataEntry_SmartICT!AA8,0)+IF(DataEntry_SmartICT!AB8<>"",DataEntry_SmartICT!AB8,0)+IF(DataEntry_SmartICT!AC8<>"",6-DataEntry_SmartICT!AC8,0)+IF(DataEntry_SmartICT!AD8<>"",DataEntry_SmartICT!AD8,0) -> 0 | K6: =IF(H6<>"",IFERROR(H6+J6,H6),"") -> 0 | L6: =IF(H6="","",IF(H6/35<=Configurazione!C21,"Trascurabile",IF(H6/35<=Configurazione!C22,"Moderato","Rilevante"))) -> Trascurabile | M6: =IF(J6=0,"N/A",IF(J6/27<=Configurazione!C26,"Trascurabile",IF(J6/27<=Configurazione!C27,"Moderato","Rilevante"))) -> N/A
A7: =DataEntry_Standard!A9 -> COMP-005 | B7: =DataEntry_Standard!C9 -> 0 | C7: =IF(DataEntry_Standard!D9<>"",DataEntry_Standard!D9,0)+IF(DataEntry_Standard!E9<>"",6-DataEntry_Standard!E9,0)+IF(DataEntry_Standard!F9<>"",6-DataEntry_Standard!F9,0)+IF(DataEntry_Standard!G9<>"",DataEntry_Standard!G9,0)+IF(DataEntry_Standard!H9<>"",6-DataEntry_Standard!H9,0)+IF(DataEntry_Standard!I9<>"",DataEntry_Standard!I9,0)+IF(DataEntry_Standard!J9<>"",DataEntry_Standard!J9,0)+IF(DataEntry_Standard!K9<>"",DataEntry_Standard!K9,0)+IF(DataEntry_Standard!L9<>"",DataEntry_Standard!L9,0)+IF(DataEntry_Standard!M9<>"",DataEntry_Standard!M9,0) -> 0 | D7: =IF(DataEntry_Standard!N9<>"",DataEntry_Standard!N9,0)+IF(DataEntry_Standard!O9<>"",DataEntry_Standard!O9,0)+IF(DataEntry_Standard!P9<>"",DataEntry_Standard!P9,0)+IF(DataEntry_Standard!Q9<>"",6-DataEntry_Standard!Q9,0)+IF(DataEntry_Standard!R9<>"",6-DataEntry_Standard!R9,0)+IF(DataEntry_Standard!S9<>"",6-DataEntry_Standard!S9,0)+IF(DataEntry_Standard!T9<>"",DataEntry_Standard!T9,0)+IF(DataEntry_Standard!U9<>"",DataEntry_Standard!U9,0)+IF(DataEntry_Standard!V9<>"",DataEntry_Standard!V9,0) -> 0 | E7: =IF(DataEntry_Standard!W9<>"",DataEntry_Standard!W9,0)+IF(DataEntry_Standard!X9<>"",6-DataEntry_Standard!X9,0)+IF(DataEntry_Standard!Y9<>"",6-DataEntry_Standard!Y9,0)+IF(DataEntry_Standard!Z9<>"",DataEntry_Standard!Z9,0)+IF(DataEntry_Standard!AA9<>"",6-DataEntry_Standard!AA9,0)+IF(DataEntry_Standard!AB9<>"",DataEntry_Standard!AB9,0)+IF(DataEntry_Standard!AC9<>"",DataEntry_Standard!AC9,0)+IF(DataEntry_Standard!AD9<>"",DataEntry_Standard!AD9,0) -> 0 | F7: =IF(DataEntry_Standard!AE9<>"",DataEntry_Standard!AE9,0)+IF(DataEntry_Standard!AF9<>"",DataEntry_Standard!AF9,0)+IF(DataEntry_Standard!AG9<>"",6-DataEntry_Standard!AG9,0)+IF(DataEntry_Standard!AH9<>"",DataEntry_Standard!AH9,0)+IF(DataEntry_Standard!AI9<>"",6-DataEntry_Standard!AI9,0) -> 0 | G7: =IF(DataEntry_Standard!AJ9<>"",DataEntry_Standard!AJ9,0)+IF(DataEntry_Standard!AK9<>"",6-DataEntry_Standard!AK9,0)+IF(DataEntry_Standard!AL9<>"",DataEntry_Standard!AL9,0) -> 0 | H7: =IF(A7<>"",C7+D7+E7+F7+G7,"") -> 0 | I7: =IF(DataEntry_Standard!D9>=4,1,0)+IF(DataEntry_Standard!G9>=4,1,0)+IF(DataEntry_Standard!I9>=4,1,0)+IF(DataEntry_Standard!J9>=4,1,0)+IF(DataEntry_Standard!K9>=4,1,0)+IF(DataEntry_Standard!L9>=4,1,0)+IF(DataEntry_Standard!M9>=4,1,0)+IF(DataEntry_Standard!N9>=4,1,0)+IF(DataEntry_Standard!O9>=4,1,0)+IF(DataEntry_Standard!P9>=4,1,0)+IF(DataEntry_Standard!T9>=4,1,0)+IF(DataEntry_Standard!U9>=4,1,0)+IF(DataEntry_Standard!V9>=4,1,0)+IF(DataEntry_Standard!W9>=4,1,0)+IF(DataEntry_Standard!Z9>=4,1,0)+IF(DataEntry_Standard!AB9>=4,1,0)+IF(DataEntry_Standard!AC9>=4,1,0)+IF(DataEntry_Standard!AD9>=4,1,0)+IF(DataEntry_Standard!AE9>=4,1,0)+IF(DataEntry_Standard!AF9>=4,1,0)+IF(DataEntry_Standard!AH9>=4,1,0)+IF(DataEntry_Standard!AJ9>=4,1,0)+IF(DataEntry_Standard!AL9>=4,1,0)+IF(DataEntry_Standard!AI9<=2,1,0)+IF(DataEntry_Standard!E9<=2,1,0)+IF(DataEntry_Standard!F9<=2,1,0)+IF(DataEntry_Standard!AK9<=2,1,0)+IF(DataEntry_Standard!H9<=2,1,0)+IF(DataEntry_Standard!Q9<=2,1,0)+IF(DataEntry_Standard!R9<=2,1,0)+IF(DataEntry_Standard!S9<=2,1,0)+IF(DataEntry_Standard!X9<=2,1,0)+IF(DataEntry_Standard!Y9<=2,1,0)+IF(DataEntry_Standard!AA9<=2,1,0)+IF(DataEntry_Standard!AG9<=2,1,0) -> 12 | J7: =IF(DataEntry_SmartICT!D9<>"",DataEntry_SmartICT!D9,0)+IF(DataEntry_SmartICT!E9<>"",DataEntry_SmartICT!E9,0)+IF(DataEntry_SmartICT!F9<>"",6-DataEntry_SmartICT!F9,0)+IF(DataEntry_SmartICT!G9<>"",6-DataEntry_SmartICT!G9,0)+IF(DataEntry_SmartICT!H9<>"",DataEntry_SmartICT!H9,0)+IF(DataEntry_SmartICT!I9<>"",DataEntry_SmartICT!I9,0)+IF(DataEntry_SmartICT!J9<>"",6-DataEntry_SmartICT!J9,0)+IF(DataEntry_SmartICT!K9<>"",DataEntry_SmartICT!K9,0)+IF(DataEntry_SmartICT!L9<>"",6-DataEntry_SmartICT!L9,0)+IF(DataEntry_SmartICT!M9<>"",DataEntry_SmartICT!M9,0)+IF(DataEntry_SmartICT!N9<>"",6-DataEntry_SmartICT!N9,0)+IF(DataEntry_SmartICT!O9<>"",6-DataEntry_SmartICT!O9,0)+IF(DataEntry_SmartICT!P9<>"",6-DataEntry_SmartICT!P9,0)+IF(DataEntry_SmartICT!Q9<>"",6-DataEntry_SmartICT!Q9,0)+IF(DataEntry_SmartICT!R9<>"",6-DataEntry_SmartICT!R9,0)+IF(DataEntry_SmartICT!S9<>"",6-DataEntry_SmartICT!S9,0)+IF(DataEntry_SmartICT!T9<>"",6-DataEntry_SmartICT!T9,0)+IF(DataEntry_SmartICT!U9<>"",6-DataEntry_SmartICT!U9,0)+IF(DataEntry_SmartICT!V9<>"",DataEntry_SmartICT!V9,0)+IF(DataEntry_SmartICT!W9<>"",DataEntry_SmartICT!W9,0)+IF(DataEntry_SmartICT!X9<>"",DataEntry_SmartICT!X9,0)+IF(DataEntry_SmartICT!Y9<>"",6-DataEntry_SmartICT!Y9,0)+IF(DataEntry_SmartICT!Z9<>"",6-DataEntry_SmartICT!Z9,0)+IF(DataEntry_SmartICT!AA9<>"",DataEntry_SmartICT!AA9,0)+IF(DataEntry_SmartICT!AB9<>"",DataEntry_SmartICT!AB9,0)+IF(DataEntry_SmartICT!AC9<>"",6-DataEntry_SmartICT!AC9,0)+IF(DataEntry_SmartICT!AD9<>"",DataEntry_SmartICT!AD9,0) -> 0 | K7: =IF(H7<>"",IFERROR(H7+J7,H7),"") -> 0 | L7: =IF(H7="","",IF(H7/35<=Configurazione!C21,"Trascurabile",IF(H7/35<=Configurazione!C22,"Moderato","Rilevante"))) -> Trascurabile | M7: =IF(J7=0,"N/A",IF(J7/27<=Configurazione!C26,"Trascurabile",IF(J7/27<=Configurazione!C27,"Moderato","Rilevante"))) -> N/A
A8: =DataEntry_Standard!A10 -> COMP-006 | B8: =DataEntry_Standard!C10 -> 0 | C8: =IF(DataEntry_Standard!D10<>"",DataEntry_Standard!D10,0)+IF(DataEntry_Standard!E10<>"",6-DataEntry_Standard!E10,0)+IF(DataEntry_Standard!F10<>"",6-DataEntry_Standard!F10,0)+IF(DataEntry_Standard!G10<>"",DataEntry_Standard!G10,0)+IF(DataEntry_Standard!H10<>"",6-DataEntry_Standard!H10,0)+IF(DataEntry_Standard!I10<>"",DataEntry_Standard!I10,0)+IF(DataEntry_Standard!J10<>"",DataEntry_Standard!J10,0)+IF(DataEntry_Standard!K10<>"",DataEntry_Standard!K10,0)+IF(DataEntry_Standard!L10<>"",DataEntry_Standard!L10,0)+IF(DataEntry_Standard!M10<>"",DataEntry_Standard!M10,0) -> 0 | D8: =IF(DataEntry_Standard!N10<>"",DataEntry_Standard!N10,0)+IF(DataEntry_Standard!O10<>"",DataEntry_Standard!O10,0)+IF(DataEntry_Standard!P10<>"",DataEntry_Standard!P10,0)+IF(DataEntry_Standard!Q10<>"",6-DataEntry_Standard!Q10,0)+IF(DataEntry_Standard!R10<>"",6-DataEntry_Standard!R10,0)+IF(DataEntry_Standard!S10<>"",6-DataEntry_Standard!S10,0)+IF(DataEntry_Standard!T10<>"",DataEntry_Standard!T10,0)+IF(DataEntry_Standard!U10<>"",DataEntry_Standard!U10,0)+IF(DataEntry_Standard!V10<>"",DataEntry_Standard!V10,0) -> 0 | E8: =IF(DataEntry_Standard!W10<>"",DataEntry_Standard!W10,0)+IF(DataEntry_Standard!X10<>"",6-DataEntry_Standard!X10,0)+IF(DataEntry_Standard!Y10<>"",6-DataEntry_Standard!Y10,0)+IF(DataEntry_Standard!Z10<>"",DataEntry_Standard!Z10,0)+IF(DataEntry_Standard!AA10<>"",6-DataEntry_Standard!AA10,0)+IF(DataEntry_Standard!AB10<>"",DataEntry_Standard!AB10,0)+IF(DataEntry_Standard!AC10<>"",DataEntry_Standard!AC10,0)+IF(DataEntry_Standard!AD10<>"",DataEntry_Standard!AD10,0) -> 0 | F8: =IF(DataEntry_Standard!AE10<>"",DataEntry_Standard!AE10,0)+IF(DataEntry_Standard!AF10<>"",DataEntry_Standard!AF10,0)+IF(DataEntry_Standard!AG10<>"",6-DataEntry_Standard!AG10,0)+IF(DataEntry_Standard!AH10<>"",DataEntry_Standard!AH10,0)+IF(DataEntry_Standard!AI10<>"",6-DataEntry_Standard!AI10,0) -> 0 | G8: =IF(DataEntry_Standard!AJ10<>"",DataEntry_Standard!AJ10,0)+IF(DataEntry_Standard!AK10<>"",6-DataEntry_Standard!AK10,0)+IF(DataEntry_Standard!AL10<>"",DataEntry_Standard!AL10,0) -> 0 | H8: =IF(A8<>"",C8+D8+E8+F8+G8,"") -> 0 | I8: =IF(DataEntry_Standard!D10>=4,1,0)+IF(DataEntry_Standard!G10>=4,1,0)+IF(DataEntry_Standard!I10>=4,1,0)+IF(DataEntry_Standard!J10>=4,1,0)+IF(DataEntry_Standard!K10>=4,1,0)+IF(DataEntry_Standard!L10>=4,1,0)+IF(DataEntry_Standard!M10>=4,1,0)+IF(DataEntry_Standard!N10>=4,1,0)+IF(DataEntry_Standard!O10>=4,1,0)+IF(DataEntry_Standard!P10>=4,1,0)+IF(DataEntry_Standard!T10>=4,1,0)+IF(DataEntry_Standard!U10>=4,1,0)+IF(DataEntry_Standard!V10>=4,1,0)+IF(DataEntry_Standard!W10>=4,1,0)+IF(DataEntry_Standard!Z10>=4,1,0)+IF(DataEntry_Standard!AB10>=4,1,0)+IF(DataEntry_Standard!AC10>=4,1,0)+IF(DataEntry_Standard!AD10>=4,1,0)+IF(DataEntry_Standard!AE10>=4,1,0)+IF(DataEntry_Standard!AF10>=4,1,0)+IF(DataEntry_Standard!AH10>=4,1,0)+IF(DataEntry_Standard!AJ10>=4,1,0)+IF(DataEntry_Standard!AL10>=4,1,0)+IF(DataEntry_Standard!AI10<=2,1,0)+IF(DataEntry_Standard!E10<=2,1,0)+IF(DataEntry_Standard!F10<=2,1,0)+IF(DataEntry_Standard!AK10<=2,1,0)+IF(DataEntry_Standard!H10<=2,1,0)+IF(DataEntry_Standard!Q10<=2,1,0)+IF(DataEntry_Standard!R10<=2,1,0)+IF(DataEntry_Standard!S10<=2,1,0)+IF(DataEntry_Standard!X10<=2,1,0)+IF(DataEntry_Standard!Y10<=2,1,0)+IF(DataEntry_Standard!AA10<=2,1,0)+IF(DataEntry_Standard!AG10<=2,1,0) -> 12 | J8: =IF(DataEntry_SmartICT!D10<>"",DataEntry_SmartICT!D10,0)+IF(DataEntry_SmartICT!E10<>"",DataEntry_SmartICT!E10,0)+IF(DataEntry_SmartICT!F10<>"",6-DataEntry_SmartICT!F10,0)+IF(DataEntry_SmartICT!G10<>"",6-DataEntry_SmartICT!G10,0)+IF(DataEntry_SmartICT!H10<>"",DataEntry_SmartICT!H10,0)+IF(DataEntry_SmartICT!I10<>"",DataEntry_SmartICT!I10,0)+IF(DataEntry_SmartICT!J10<>"",6-DataEntry_SmartICT!J10,0)+IF(DataEntry_SmartICT!K10<>"",DataEntry_SmartICT!K10,0)+IF(DataEntry_SmartICT!L10<>"",6-DataEntry_SmartICT!L10,0)+IF(DataEntry_SmartICT!M10<>"",DataEntry_SmartICT!M10,0)+IF(DataEntry_SmartICT!N10<>"",6-DataEntry_SmartICT!N10,0)+IF(DataEntry_SmartICT!O10<>"",6-DataEntry_SmartICT!O10,0)+IF(DataEntry_SmartICT!P10<>"",6-DataEntry_SmartICT!P10,0)+IF(DataEntry_SmartICT!Q10<>"",6-DataEntry_SmartICT!Q10,0)+IF(DataEntry_SmartICT!R10<>"",6-DataEntry_SmartICT!R10,0)+IF(DataEntry_SmartICT!S10<>"",6-DataEntry_SmartICT!S10,0)+IF(DataEntry_SmartICT!T10<>"",6-DataEntry_SmartICT!T10,0)+IF(DataEntry_SmartICT!U10<>"",6-DataEntry_SmartICT!U10,0)+IF(DataEntry_SmartICT!V10<>"",DataEntry_SmartICT!V10,0)+IF(DataEntry_SmartICT!W10<>"",DataEntry_SmartICT!W10,0)+IF(DataEntry_SmartICT!X10<>"",DataEntry_SmartICT!X10,0)+IF(DataEntry_SmartICT!Y10<>"",6-DataEntry_SmartICT!Y10,0)+IF(DataEntry_SmartICT!Z10<>"",6-DataEntry_SmartICT!Z10,0)+IF(DataEntry_SmartICT!AA10<>"",DataEntry_SmartICT!AA10,0)+IF(DataEntry_SmartICT!AB10<>"",DataEntry_SmartICT!AB10,0)+IF(DataEntry_SmartICT!AC10<>"",6-DataEntry_SmartICT!AC10,0)+IF(DataEntry_SmartICT!AD10<>"",DataEntry_SmartICT!AD10,0) -> 0 | K8: =IF(H8<>"",IFERROR(H8+J8,H8),"") -> 0 | L8: =IF(H8="","",IF(H8/35<=Configurazione!C21,"Trascurabile",IF(H8/35<=Configurazione!C22,"Moderato","Rilevante"))) -> Trascurabile | M8: =IF(J8=0,"N/A",IF(J8/27<=Configurazione!C26,"Trascurabile",IF(J8/27<=Configurazione!C27,"Moderato","Rilevante"))) -> N/A
A9: =DataEntry_Standard!A11 -> COMP-007 | B9: =DataEntry_Standard!C11 -> 0 | C9: =IF(DataEntry_Standard!D11<>"",DataEntry_Standard!D11,0)+IF(DataEntry_Standard!E11<>"",6-DataEntry_Standard!E11,0)+IF(DataEntry_Standard!F11<>"",6-DataEntry_Standard!F11,0)+IF(DataEntry_Standard!G11<>"",DataEntry_Standard!G11,0)+IF(DataEntry_Standard!H11<>"",6-DataEntry_Standard!H11,0)+IF(DataEntry_Standard!I11<>"",DataEntry_Standard!I11,0)+IF(DataEntry_Standard!J11<>"",DataEntry_Standard!J11,0)+IF(DataEntry_Standard!K11<>"",DataEntry_Standard!K11,0)+IF(DataEntry_Standard!L11<>"",DataEntry_Standard!L11,0)+IF(DataEntry_Standard!M11<>"",DataEntry_Standard!M11,0) -> 0 | D9: =IF(DataEntry_Standard!N11<>"",DataEntry_Standard!N11,0)+IF(DataEntry_Standard!O11<>"",DataEntry_Standard!O11,0)+IF(DataEntry_Standard!P11<>"",DataEntry_Standard!P11,0)+IF(DataEntry_Standard!Q11<>"",6-DataEntry_Standard!Q11,0)+IF(DataEntry_Standard!R11<>"",6-DataEntry_Standard!R11,0)+IF(DataEntry_Standard!S11<>"",6-DataEntry_Standard!S11,0)+IF(DataEntry_Standard!T11<>"",DataEntry_Standard!T11,0)+IF(DataEntry_Standard!U11<>"",DataEntry_Standard!U11,0)+IF(DataEntry_Standard!V11<>"",DataEntry_Standard!V11,0) -> 0 | E9: =IF(DataEntry_Standard!W11<>"",DataEntry_Standard!W11,0)+IF(DataEntry_Standard!X11<>"",6-DataEntry_Standard!X11,0)+IF(DataEntry_Standard!Y11<>"",6-DataEntry_Standard!Y11,0)+IF(DataEntry_Standard!Z11<>"",DataEntry_Standard!Z11,0)+IF(DataEntry_Standard!AA11<>"",6-DataEntry_Standard!AA11,0)+IF(DataEntry_Standard!AB11<>"",DataEntry_Standard!AB11,0)+IF(DataEntry_Standard!AC11<>"",DataEntry_Standard!AC11,0)+IF(DataEntry_Standard!AD11<>"",DataEntry_Standard!AD11,0) -> 0 | F9: =IF(DataEntry_Standard!AE11<>"",DataEntry_Standard!AE11,0)+IF(DataEntry_Standard!AF11<>"",DataEntry_Standard!AF11,0)+IF(DataEntry_Standard!AG11<>"",6-DataEntry_Standard!AG11,0)+IF(DataEntry_Standard!AH11<>"",DataEntry_Standard!AH11,0)+IF(DataEntry_Standard!AI11<>"",6-DataEntry_Standard!AI11,0) -> 0 | G9: =IF(DataEntry_Standard!AJ11<>"",DataEntry_Standard!AJ11,0)+IF(DataEntry_Standard!AK11<>"",6-DataEntry_Standard!AK11,0)+IF(DataEntry_Standard!AL11<>"",DataEntry_Standard!AL11,0) -> 0 | H9: =IF(A9<>"",C9+D9+E9+F9+G9,"") -> 0 | I9: =IF(DataEntry_Standard!D11>=4,1,0)+IF(DataEntry_Standard!G11>=4,1,0)+IF(DataEntry_Standard!I11>=4,1,0)+IF(DataEntry_Standard!J11>=4,1,0)+IF(DataEntry_Standard!K11>=4,1,0)+IF(DataEntry_Standard!L11>=4,1,0)+IF(DataEntry_Standard!M11>=4,1,0)+IF(DataEntry_Standard!N11>=4,1,0)+IF(DataEntry_Standard!O11>=4,1,0)+IF(DataEntry_Standard!P11>=4,1,0)+IF(DataEntry_Standard!T11>=4,1,0)+IF(DataEntry_Standard!U11>=4,1,0)+IF(DataEntry_Standard!V11>=4,1,0)+IF(DataEntry_Standard!W11>=4,1,0)+IF(DataEntry_Standard!Z11>=4,1,0)+IF(DataEntry_Standard!AB11>=4,1,0)+IF(DataEntry_Standard!AC11>=4,1,0)+IF(DataEntry_Standard!AD11>=4,1,0)+IF(DataEntry_Standard!AE11>=4,1,0)+IF(DataEntry_Standard!AF11>=4,1,0)+IF(DataEntry_Standard!AH11>=4,1,0)+IF(DataEntry_Standard!AJ11>=4,1,0)+IF(DataEntry_Standard!AL11>=4,1,0)+IF(DataEntry_Standard!AI11<=2,1,0)+IF(DataEntry_Standard!E11<=2,1,0)+IF(DataEntry_Standard!F11<=2,1,0)+IF(DataEntry_Standard!AK11<=2,1,0)+IF(DataEntry_Standard!H11<=2,1,0)+IF(DataEntry_Standard!Q11<=2,1,0)+IF(DataEntry_Standard!R11<=2,1,0)+IF(DataEntry_Standard!S11<=2,1,0)+IF(DataEntry_Standard!X11<=2,1,0)+IF(DataEntry_Standard!Y11<=2,1,0)+IF(DataEntry_Standard!AA11<=2,1,0)+IF(DataEntry_Standard!AG11<=2,1,0) -> 12 | J9: =IF(DataEntry_SmartICT!D11<>"",DataEntry_SmartICT!D11,0)+IF(DataEntry_SmartICT!E11<>"",DataEntry_SmartICT!E11,0)+IF(DataEntry_SmartICT!F11<>"",6-DataEntry_SmartICT!F11,0)+IF(DataEntry_SmartICT!G11<>"",6-DataEntry_SmartICT!G11,0)+IF(DataEntry_SmartICT!H11<>"",DataEntry_SmartICT!H11,0)+IF(DataEntry_SmartICT!I11<>"",DataEntry_SmartICT!I11,0)+IF(DataEntry_SmartICT!J11<>"",6-DataEntry_SmartICT!J11,0)+IF(DataEntry_SmartICT!K11<>"",DataEntry_SmartICT!K11,0)+IF(DataEntry_SmartICT!L11<>"",6-DataEntry_SmartICT!L11,0)+IF(DataEntry_SmartICT!M11<>"",DataEntry_SmartICT!M11,0)+IF(DataEntry_SmartICT!N11<>"",6-DataEntry_SmartICT!N11,0)+IF(DataEntry_SmartICT!O11<>"",6-DataEntry_SmartICT!O11,0)+IF(DataEntry_SmartICT!P11<>"",6-DataEntry_SmartICT!P11,0)+IF(DataEntry_SmartICT!Q11<>"",6-DataEntry_SmartICT!Q11,0)+IF(DataEntry_SmartICT!R11<>"",6-DataEntry_SmartICT!R11,0)+IF(DataEntry_SmartICT!S11<>"",6-DataEntry_SmartICT!S11,0)+IF(DataEntry_SmartICT!T11<>"",6-DataEntry_SmartICT!T11,0)+IF(DataEntry_SmartICT!U11<>"",6-DataEntry_SmartICT!U11,0)+IF(DataEntry_SmartICT!V11<>"",DataEntry_SmartICT!V11,0)+IF(DataEntry_SmartICT!W11<>"",DataEntry_SmartICT!W11,0)+IF(DataEntry_SmartICT!X11<>"",DataEntry_SmartICT!X11,0)+IF(DataEntry_SmartICT!Y11<>"",6-DataEntry_SmartICT!Y11,0)+IF(DataEntry_SmartICT!Z11<>"",6-DataEntry_SmartICT!Z11,0)+IF(DataEntry_SmartICT!AA11<>"",DataEntry_SmartICT!AA11,0)+IF(DataEntry_SmartICT!AB11<>"",DataEntry_SmartICT!AB11,0)+IF(DataEntry_SmartICT!AC11<>"",6-DataEntry_SmartICT!AC11,0)+IF(DataEntry_SmartICT!AD11<>"",DataEntry_SmartICT!AD11,0) -> 0 | K9: =IF(H9<>"",IFERROR(H9+J9,H9),"") -> 0 | L9: =IF(H9="","",IF(H9/35<=Configurazione!C21,"Trascurabile",IF(H9/35<=Configurazione!C22,"Moderato","Rilevante"))) -> Trascurabile | M9: =IF(J9=0,"N/A",IF(J9/27<=Configurazione!C26,"Trascurabile",IF(J9/27<=Configurazione!C27,"Moderato","Rilevante"))) -> N/A
A10: =DataEntry_Standard!A12 -> COMP-008 | B10: =DataEntry_Standard!C12 -> 0 | C10: =IF(DataEntry_Standard!D12<>"",DataEntry_Standard!D12,0)+IF(DataEntry_Standard!E12<>"",6-DataEntry_Standard!E12,0)+IF(DataEntry_Standard!F12<>"",6-DataEntry_Standard!F12,0)+IF(DataEntry_Standard!G12<>"",DataEntry_Standard!G12,0)+IF(DataEntry_Standard!H12<>"",6-DataEntry_Standard!H12,0)+IF(DataEntry_Standard!I12<>"",DataEntry_Standard!I12,0)+IF(DataEntry_Standard!J12<>"",DataEntry_Standard!J12,0)+IF(DataEntry_Standard!K12<>"",DataEntry_Standard!K12,0)+IF(DataEntry_Standard!L12<>"",DataEntry_Standard!L12,0)+IF(DataEntry_Standard!M12<>"",DataEntry_Standard!M12,0) -> 0 | D10: =IF(DataEntry_Standard!N12<>"",DataEntry_Standard!N12,0)+IF(DataEntry_Standard!O12<>"",DataEntry_Standard!O12,0)+IF(DataEntry_Standard!P12<>"",DataEntry_Standard!P12,0)+IF(DataEntry_Standard!Q12<>"",6-DataEntry_Standard!Q12,0)+IF(DataEntry_Standard!R12<>"",6-DataEntry_Standard!R12,0)+IF(DataEntry_Standard!S12<>"",6-DataEntry_Standard!S12,0)+IF(DataEntry_Standard!T12<>"",DataEntry_Standard!T12,0)+IF(DataEntry_Standard!U12<>"",DataEntry_Standard!U12,0)+IF(DataEntry_Standard!V12<>"",DataEntry_Standard!V12,0) -> 0 | E10: =IF(DataEntry_Standard!W12<>"",DataEntry_Standard!W12,0)+IF(DataEntry_Standard!X12<>"",6-DataEntry_Standard!X12,0)+IF(DataEntry_Standard!Y12<>"",6-DataEntry_Standard!Y12,0)+IF(DataEntry_Standard!Z12<>"",DataEntry_Standard!Z12,0)+IF(DataEntry_Standard!AA12<>"",6-DataEntry_Standard!AA12,0)+IF(DataEntry_Standard!AB12<>"",DataEntry_Standard!AB12,0)+IF(DataEntry_Standard!AC12<>"",DataEntry_Standard!AC12,0)+IF(DataEntry_Standard!AD12<>"",DataEntry_Standard!AD12,0) -> 0 | F10: =IF(DataEntry_Standard!AE12<>"",DataEntry_Standard!AE12,0)+IF(DataEntry_Standard!AF12<>"",DataEntry_Standard!AF12,0)+IF(DataEntry_Standard!AG12<>"",6-DataEntry_Standard!AG12,0)+IF(DataEntry_Standard!AH12<>"",DataEntry_Standard!AH12,0)+IF(DataEntry_Standard!AI12<>"",6-DataEntry_Standard!AI12,0) -> 0 | G10: =IF(DataEntry_Standard!AJ12<>"",DataEntry_Standard!AJ12,0)+IF(DataEntry_Standard!AK12<>"",6-DataEntry_Standard!AK12,0)+IF(DataEntry_Standard!AL12<>"",DataEntry_Standard!AL12,0) -> 0 | H10: =IF(A10<>"",C10+D10+E10+F10+G10,"") -> 0 | I10: =IF(DataEntry_Standard!D12>=4,1,0)+IF(DataEntry_Standard!G12>=4,1,0)+IF(DataEntry_Standard!I12>=4,1,0)+IF(DataEntry_Standard!J12>=4,1,0)+IF(DataEntry_Standard!K12>=4,1,0)+IF(DataEntry_Standard!L12>=4,1,0)+IF(DataEntry_Standard!M12>=4,1,0)+IF(DataEntry_Standard!N12>=4,1,0)+IF(DataEntry_Standard!O12>=4,1,0)+IF(DataEntry_Standard!P12>=4,1,0)+IF(DataEntry_Standard!T12>=4,1,0)+IF(DataEntry_Standard!U12>=4,1,0)+IF(DataEntry_Standard!V12>=4,1,0)+IF(DataEntry_Standard!W12>=4,1,0)+IF(DataEntry_Standard!Z12>=4,1,0)+IF(DataEntry_Standard!AB12>=4,1,0)+IF(DataEntry_Standard!AC12>=4,1,0)+IF(DataEntry_Standard!AD12>=4,1,0)+IF(DataEntry_Standard!AE12>=4,1,0)+IF(DataEntry_Standard!AF12>=4,1,0)+IF(DataEntry_Standard!AH12>=4,1,0)+IF(DataEntry_Standard!AJ12>=4,1,0)+IF(DataEntry_Standard!AL12>=4,1,0)+IF(DataEntry_Standard!AI12<=2,1,0)+IF(DataEntry_Standard!E12<=2,1,0)+IF(DataEntry_Standard!F12<=2,1,0)+IF(DataEntry_Standard!AK12<=2,1,0)+IF(DataEntry_Standard!H12<=2,1,0)+IF(DataEntry_Standard!Q12<=2,1,0)+IF(DataEntry_Standard!R12<=2,1,0)+IF(DataEntry_Standard!S12<=2,1,0)+IF(DataEntry_Standard!X12<=2,1,0)+IF(DataEntry_Standard!Y12<=2,1,0)+IF(DataEntry_Standard!AA12<=2,1,0)+IF(DataEntry_Standard!AG12<=2,1,0) -> 12 | J10: =IF(DataEntry_SmartICT!D12<>"",DataEntry_SmartICT!D12,0)+IF(DataEntry_SmartICT!E12<>"",DataEntry_SmartICT!E12,0)+IF(DataEntry_SmartICT!F12<>"",6-DataEntry_SmartICT!F12,0)+IF(DataEntry_SmartICT!G12<>"",6-DataEntry_SmartICT!G12,0)+IF(DataEntry_SmartICT!H12<>"",DataEntry_SmartICT!H12,0)+IF(DataEntry_SmartICT!I12<>"",DataEntry_SmartICT!I12,0)+IF(DataEntry_SmartICT!J12<>"",6-DataEntry_SmartICT!J12,0)+IF(DataEntry_SmartICT!K12<>"",DataEntry_SmartICT!K12,0)+IF(DataEntry_SmartICT!L12<>"",6-DataEntry_SmartICT!L12,0)+IF(DataEntry_SmartICT!M12<>"",DataEntry_SmartICT!M12,0)+IF(DataEntry_SmartICT!N12<>"",6-DataEntry_SmartICT!N12,0)+IF(DataEntry_SmartICT!O12<>"",6-DataEntry_SmartICT!O12,0)+IF(DataEntry_SmartICT!P12<>"",6-DataEntry_SmartICT!P12,0)+IF(DataEntry_SmartICT!Q12<>"",6-DataEntry_SmartICT!Q12,0)+IF(DataEntry_SmartICT!R12<>"",6-DataEntry_SmartICT!R12,0)+IF(DataEntry_SmartICT!S12<>"",6-DataEntry_SmartICT!S12,0)+IF(DataEntry_SmartICT!T12<>"",6-DataEntry_SmartICT!T12,0)+IF(DataEntry_SmartICT!U12<>"",6-DataEntry_SmartICT!U12,0)+IF(DataEntry_SmartICT!V12<>"",DataEntry_SmartICT!V12,0)+IF(DataEntry_SmartICT!W12<>"",DataEntry_SmartICT!W12,0)+IF(DataEntry_SmartICT!X12<>"",DataEntry_SmartICT!X12,0)+IF(DataEntry_SmartICT!Y12<>"",6-DataEntry_SmartICT!Y12,0)+IF(DataEntry_SmartICT!Z12<>"",6-DataEntry_SmartICT!Z12,0)+IF(DataEntry_SmartICT!AA12<>"",DataEntry_SmartICT!AA12,0)+IF(DataEntry_SmartICT!AB12<>"",DataEntry_SmartICT!AB12,0)+IF(DataEntry_SmartICT!AC12<>"",6-DataEntry_SmartICT!AC12,0)+IF(DataEntry_SmartICT!AD12<>"",DataEntry_SmartICT!AD12,0) -> 0 | K10: =IF(H10<>"",IFERROR(H10+J10,H10),"") -> 0 | L10: =IF(H10="","",IF(H10/35<=Configurazione!C21,"Trascurabile",IF(H10/35<=Configurazione!C22,"Moderato","Rilevante"))) -> Trascurabile | M10: =IF(J10=0,"N/A",IF(J10/27<=Configurazione!C26,"Trascurabile",IF(J10/27<=Configurazione!C27,"Moderato","Rilevante"))) -> N/A
A11: =DataEntry_Standard!A13 -> COMP-009 | B11: =DataEntry_Standard!C13 -> 0 | C11: =IF(DataEntry_Standard!D13<>"",DataEntry_Standard!D13,0)+IF(DataEntry_Standard!E13<>"",6-DataEntry_Standard!E13,0)+IF(DataEntry_Standard!F13<>"",6-DataEntry_Standard!F13,0)+IF(DataEntry_Standard!G13<>"",DataEntry_Standard!G13,0)+IF(DataEntry_Standard!H13<>"",6-DataEntry_Standard!H13,0)+IF(DataEntry_Standard!I13<>"",DataEntry_Standard!I13,0)+IF(DataEntry_Standard!J13<>"",DataEntry_Standard!J13,0)+IF(DataEntry_Standard!K13<>"",DataEntry_Standard!K13,0)+IF(DataEntry_Standard!L13<>"",DataEntry_Standard!L13,0)+IF(DataEntry_Standard!M13<>"",DataEntry_Standard!M13,0) -> 0 | D11: =IF(DataEntry_Standard!N13<>"",DataEntry_Standard!N13,0)+IF(DataEntry_Standard!O13<>"",DataEntry_Standard!O13,0)+IF(DataEntry_Standard!P13<>"",DataEntry_Standard!P13,0)+IF(DataEntry_Standard!Q13<>"",6-DataEntry_Standard!Q13,0)+IF(DataEntry_Standard!R13<>"",6-DataEntry_Standard!R13,0)+IF(DataEntry_Standard!S13<>"",6-DataEntry_Standard!S13,0)+IF(DataEntry_Standard!T13<>"",DataEntry_Standard!T13,0)+IF(DataEntry_Standard!U13<>"",DataEntry_Standard!U13,0)+IF(DataEntry_Standard!V13<>"",DataEntry_Standard!V13,0) -> 0 | E11: =IF(DataEntry_Standard!W13<>"",DataEntry_Standard!W13,0)+IF(DataEntry_Standard!X13<>"",6-DataEntry_Standard!X13,0)+IF(DataEntry_Standard!Y13<>"",6-DataEntry_Standard!Y13,0)+IF(DataEntry_Standard!Z13<>"",DataEntry_Standard!Z13,0)+IF(DataEntry_Standard!AA13<>"",6-DataEntry_Standard!AA13,0)+IF(DataEntry_Standard!AB13<>"",DataEntry_Standard!AB13,0)+IF(DataEntry_Standard!AC13<>"",DataEntry_Standard!AC13,0)+IF(DataEntry_Standard!AD13<>"",DataEntry_Standard!AD13,0) -> 0 | F11: =IF(DataEntry_Standard!AE13<>"",DataEntry_Standard!AE13,0)+IF(DataEntry_Standard!AF13<>"",DataEntry_Standard!AF13,0)+IF(DataEntry_Standard!AG13<>"",6-DataEntry_Standard!AG13,0)+IF(DataEntry_Standard!AH13<>"",DataEntry_Standard!AH13,0)+IF(DataEntry_Standard!AI13<>"",6-DataEntry_Standard!AI13,0) -> 0 | G11: =IF(DataEntry_Standard!AJ13<>"",DataEntry_Standard!AJ13,0)+IF(DataEntry_Standard!AK13<>"",6-DataEntry_Standard!AK13,0)+IF(DataEntry_Standard!AL13<>"",DataEntry_Standard!AL13,0) -> 0 | H11: =IF(A11<>"",C11+D11+E11+F11+G11,"") -> 0 | I11: =IF(DataEntry_Standard!D13>=4,1,0)+IF(DataEntry_Standard!G13>=4,1,0)+IF(DataEntry_Standard!I13>=4,1,0)+IF(DataEntry_Standard!J13>=4,1,0)+IF(DataEntry_Standard!K13>=4,1,0)+IF(DataEntry_Standard!L13>=4,1,0)+IF(DataEntry_Standard!M13>=4,1,0)+IF(DataEntry_Standard!N13>=4,1,0)+IF(DataEntry_Standard!O13>=4,1,0)+IF(DataEntry_Standard!P13>=4,1,0)+IF(DataEntry_Standard!T13>=4,1,0)+IF(DataEntry_Standard!U13>=4,1,0)+IF(DataEntry_Standard!V13>=4,1,0)+IF(DataEntry_Standard!W13>=4,1,0)+IF(DataEntry_Standard!Z13>=4,1,0)+IF(DataEntry_Standard!AB13>=4,1,0)+IF(DataEntry_Standard!AC13>=4,1,0)+IF(DataEntry_Standard!AD13>=4,1,0)+IF(DataEntry_Standard!AE13>=4,1,0)+IF(DataEntry_Standard!AF13>=4,1,0)+IF(DataEntry_Standard!AH13>=4,1,0)+IF(DataEntry_Standard!AJ13>=4,1,0)+IF(DataEntry_Standard!AL13>=4,1,0)+IF(DataEntry_Standard!AI13<=2,1,0)+IF(DataEntry_Standard!E13<=2,1,0)+IF(DataEntry_Standard!F13<=2,1,0)+IF(DataEntry_Standard!AK13<=2,1,0)+IF(DataEntry_Standard!H13<=2,1,0)+IF(DataEntry_Standard!Q13<=2,1,0)+IF(DataEntry_Standard!R13<=2,1,0)+IF(DataEntry_Standard!S13<=2,1,0)+IF(DataEntry_Standard!X13<=2,1,0)+IF(DataEntry_Standard!Y13<=2,1,0)+IF(DataEntry_Standard!AA13<=2,1,0)+IF(DataEntry_Standard!AG13<=2,1,0) -> 12 | J11: =IF(DataEntry_SmartICT!D13<>"",DataEntry_SmartICT!D13,0)+IF(DataEntry_SmartICT!E13<>"",DataEntry_SmartICT!E13,0)+IF(DataEntry_SmartICT!F13<>"",6-DataEntry_SmartICT!F13,0)+IF(DataEntry_SmartICT!G13<>"",6-DataEntry_SmartICT!G13,0)+IF(DataEntry_SmartICT!H13<>"",DataEntry_SmartICT!H13,0)+IF(DataEntry_SmartICT!I13<>"",DataEntry_SmartICT!I13,0)+IF(DataEntry_SmartICT!J13<>"",6-DataEntry_SmartICT!J13,0)+IF(DataEntry_SmartICT!K13<>"",DataEntry_SmartICT!K13,0)+IF(DataEntry_SmartICT!L13<>"",6-DataEntry_SmartICT!L13,0)+IF(DataEntry_SmartICT!M13<>"",DataEntry_SmartICT!M13,0)+IF(DataEntry_SmartICT!N13<>"",6-DataEntry_SmartICT!N13,0)+IF(DataEntry_SmartICT!O13<>"",6-DataEntry_SmartICT!O13,0)+IF(DataEntry_SmartICT!P13<>"",6-DataEntry_SmartICT!P13,0)+IF(DataEntry_SmartICT!Q13<>"",6-DataEntry_SmartICT!Q13,0)+IF(DataEntry_SmartICT!R13<>"",6-DataEntry_SmartICT!R13,0)+IF(DataEntry_SmartICT!S13<>"",6-DataEntry_SmartICT!S13,0)+IF(DataEntry_SmartICT!T13<>"",6-DataEntry_SmartICT!T13,0)+IF(DataEntry_SmartICT!U13<>"",6-DataEntry_SmartICT!U13,0)+IF(DataEntry_SmartICT!V13<>"",DataEntry_SmartICT!V13,0)+IF(DataEntry_SmartICT!W13<>"",DataEntry_SmartICT!W13,0)+IF(DataEntry_SmartICT!X13<>"",DataEntry_SmartICT!X13,0)+IF(DataEntry_SmartICT!Y13<>"",6-DataEntry_SmartICT!Y13,0)+IF(DataEntry_SmartICT!Z13<>"",6-DataEntry_SmartICT!Z13,0)+IF(DataEntry_SmartICT!AA13<>"",DataEntry_SmartICT!AA13,0)+IF(DataEntry_SmartICT!AB13<>"",DataEntry_SmartICT!AB13,0)+IF(DataEntry_SmartICT!AC13<>"",6-DataEntry_SmartICT!AC13,0)+IF(DataEntry_SmartICT!AD13<>"",DataEntry_SmartICT!AD13,0) -> 0 | K11: =IF(H11<>"",IFERROR(H11+J11,H11),"") -> 0 | L11: =IF(H11="","",IF(H11/35<=Configurazione!C21,"Trascurabile",IF(H11/35<=Configurazione!C22,"Moderato","Rilevante"))) -> Trascurabile | M11: =IF(J11=0,"N/A",IF(J11/27<=Configurazione!C26,"Trascurabile",IF(J11/27<=Configurazione!C27,"Moderato","Rilevante"))) -> N/A
